anomaly_degree,content
0.2,"INFO       org.apache.hadoop.yarn.server.resourcemanager.rmapp.RMAppImpl: Application application_1527018750538_0001 failed 2 times due to Error launching appattempt_1527018750538_0001_000002. Got exception: java.net.ConnectException: Call From NameNode/193.198.139.50 to localhost:41227 failed on connection exception: java.net.ConnectException: Connection refused; For more details see:  http://wiki.apache.org/hadoop/ConnectionRefused
    at sun.reflect.GeneratedConstructorAccessor47.newInstance(Unknown Source)
    at sun.reflect.DelegatingConstructorAccessorImpl.newInstance(DelegatingConstructorAccessorImpl.java:45)
    at java.lang.reflect.Constructor.newInstance(Constructor.java:423)
    at org.apache.hadoop.net.NetUtils.wrapWithMessage(NetUtils.java:792)
    at org.apache.hadoop.net.NetUtils.wrapException(NetUtils.java:732)
    at org.apache.hadoop.ipc.Client.call(Client.java:1480)
    at org.apache.hadoop.ipc.Client.call(Client.java:1413)
    at org.apache.hadoop.ipc.ProtobufRpcEngine$Invoker.invoke(ProtobufRpcEngine.java:229)
    at com.sun.proxy.$Proxy83.startContainers(Unknown Source)
    at org.apache.hadoop.yarn.api.impl.pb.client.ContainerManagementProtocolPBClientImpl.startContainers(ContainerManagementProtocolPBClientImpl.java:96)
    at sun.reflect.GeneratedMethodAccessor14.invoke(Unknown Source)
    at sun.reflect.DelegatingMethodAccessorImpl.invoke(DelegatingMethodAccessorImpl.java:43)
    at java.lang.reflect.Method.invoke(Method.java:498)
    at org.apache.hadoop.io.retry.RetryInvocationHandler.invokeMethod(RetryInvocationHandler.java:191)
    at org.apache.hadoop.io.retry.RetryInvocationHandler.invoke(RetryInvocationHandler.java:102)
    at com.sun.proxy.$Proxy84.startContainers(Unknown Source)
    at org.apache.hadoop.yarn.server.resourcemanager.amlauncher.AMLauncher.launch(AMLauncher.java:119)
    at org.apache.hadoop.yarn.server.resourcemanager.amlauncher.AMLauncher.run(AMLauncher.java:250)
    at java.util.concurrent.ThreadPoolExecutor.runWorker(ThreadPoolExecutor.java:1149)
    at java.util.concurrent.ThreadPoolExecutor$Worker.run(ThreadPoolExecutor.java:624)
    at java.lang.Thread.run(Thread.java:748)
Caused by: java.net.ConnectException: Connection refused
    at sun.nio.ch.SocketChannelImpl.checkConnect(Native Method)
    at sun.nio.ch.SocketChannelImpl.finishConnect(SocketChannelImpl.java:717)
    at org.apache.hadoop.net.SocketIOWithTimeout.connect(SocketIOWithTimeout.java:206)
    at org.apache.hadoop.net.NetUtils.connect(NetUtils.java:531)
    at org.apache.hadoop.net.NetUtils.connect(NetUtils.java:495)
    at org.apache.hadoop.ipc.Client$Connection.setupConnection(Client.java:615)
    at org.apache.hadoop.ipc.Client$Connection.setupIOstreams(Client.java:713)
    at org.apache.hadoop.ipc.Client$Connection.access$2900(Client.java:376)
    at org.apache.hadoop.ipc.Client.getConnection(Client.java:1529)
    at org.apache.hadoop.ipc.Client.call(Client.java:1452)
    ... 15 more
. Failing the application"
